Workbook
Name SegmentaciónDeDatos_Año: #N/A
Name SegmentaciónDeDatos_Año1: #N/A
Name SegmentaciónDeDatos_Año2: #N/A
Name SegmentaciónDeDatos_Tipo: #N/A
Name SegmentaciónDeDatos_Tipo1: #N/A

Sheet Notas
B2: Empresa "Andes Finance Group" S.A
B3: Notas a los estados finacieros | G3: Código de cifras
B4: Nota: Cifras auditadas en miles de dólares estadounidenses | G4: Tipo | H4: Color | I4: Código
G5: Constante | H5: Azul | I5: RGB 0,0,255
B6: PARTE 1 - Cuentas de resultados | G6: Referencia | H6: Verde | I6: RGB 0,176,80
G7: Operación | H7: Negro | I7: RGB 64,64,64
B8: Nota 1. Ingresos por venta
B9: Ingresos por venta | C9: Año 1 | D9: Año 2 | E9: Año 3
B10: Ingresos | C10: 2400 | D10: 2900 | E10: 3404
B12: Nota 2. Costos de venta
B13: Costos de venta | C13: Año 1 | D13: Año 2 | E13: Año 3
B14: Costos directos | C14: 1000 | D14: 1200 | E14: 1217.2
B15: Costos indirectos | C15: 440 | D15: 482 | E15: 700
B16: Costo de venta | C16: =+SUM(C14:C15) -> 1440 | D16: =+SUM(D14:D15) -> 1682 | E16: =+SUM(E14:E15) -> 1917.2
B18: Nota 3. Gastos operativos
B19: Gastos operativos | C19: Año 1 | D19: Año 2 | E19: Año 3
B20: Gastos de venta | C20: 316 | D20: 361 | E20: 397.36
B21: Gastos administrativos | C21: 301 | D21: 381 | E21: 427.84
B22: Gasto de depreciación | C22: =+C76 -> 80 | D22: =+D76 -> 91 | E22: =+E76 -> 93
B23: Gasto de amortización | C23: =+C92 -> 23 | D23: =+D92 -> 25 | E23: =+E92 -> 26
B24: Gastos operativos | C24: =+SUM(C20:C23) -> 720 | D24: =+SUM(D20:D23) -> 858 | E24: =+SUM(E20:E23) -> 944.2
B26: Nota 4. Otros ingresos y gastos no operativos
B27: Otros ingresos / gastos | C27: Año 1 | D27: Año 2 | E27: Año 3
B28: Ingresos no operativos | C28: 4 | D28: 8 | E28: 4
B29: Gastos no operativos | C29: 4 | D29: 4 | E29: 6
B31: Nota 5. Tasa impositiva y de reserva legal
B32: Impuestos y reserva legal | C32: Año 1 | D32: Año 2 | E32: Año 3
B33: Tasa impositiva (%) | C33: 0.25 | D33: 0.25 | E33: 0.25
B34: Reserva legal (% de UAIR)* | C34: 0.07 | D34: 0.07 | E34: 0.07
B35: *Siempre y cuando el acumulado no sobrepase una quinta parte del capital social.
B37: PARTE 2 - Cuentas de balance
B39: Nota 6. Efectivo y equivalentes
B40: Efectivo y equivalentes | C40: Año 1 | D40: Año 2 | E40: Año 3
B41: Efectivo | C41: 125.1 | D41: 81.55 | E41: 143.7
B42: Depósitos | C42: 122 | D42: 53 | E42: 166.25
B43: Efectivo y equivalentes | C43: =+SUM(C41:C42) -> 247.1 | D43: =+SUM(D41:D42) -> 134.55 | E43: =+SUM(E41:E42) -> 309.95
B45: Nota 7. Clientes
B46: Cuentas por cobrar | C46: Año 1 | D46: Año 2 | E46: Año 3
B47: Cuentas por cobrar brutas | C47: 480 | D47: 650 | E47: 820 | G47: =C48/C47 -> -0.10416667
B48: Incobrables | C48: -50 | D48: -60 | E48: -72
...

Sheet EEFF
B2: Empresa "Andes Finance Group" S.A
B3: Estados financieros | G3: Análisis vertical | L3: Análisis horizontal
B4: Nota: Cifras auditadas en miles de dólares estadounidenses
B6: Estado de resultados | C6: Año 1 | D6: Año 2 | E6: Año 3 | G6: ER (en % de ingresos) | H6: Año 1 | I6: Año 2 | J6: Año 3 | L6: ER (Cambio % | crecimiento) | M6: Año 1 | N6: Año 2 | O6: Año 3 | Q6: ER (Cambio $) | R6: Año 1 | S6: Año 2 | T6: Año 3
B7: Ingresos | C7: =+Notas!C10 -> 2400 | D7: =+Notas!D10 -> 2900 | E7: =+Notas!E10 -> 3404 | G7: Ingresos | H7: =C7/C$7 -> 1 | I7: =D7/D$7 -> 1 | J7: =E7/E$7 -> 1 | L7: Ingresos | N7: =D7/C7-1 -> 0.20833333 | O7: =E7/D7-1 -> 0.1737931 | Q7: Ingresos | S7: =+D7-C7 -> 500 | T7: =+E7-D7 -> 504
B8: Costos | C8: =+Notas!C16 -> 1440 | D8: =+Notas!D16 -> 1682 | E8: =+Notas!E16 -> 1917.2 | G8: Costos | H8: =C8/C$7 -> 0.6 | I8: =D8/D$7 -> 0.58 | J8: =E8/E$7 -> 0.56321974 | L8: Costos | N8: =D8/C8-1 -> 0.16805556 | O8: =E8/D8-1 -> 0.13983353 | Q8: Costos | S8: =+D8-C8 -> 242 | T8: =+E8-D8 -> 235.2
B9: Utilidad bruta | C9: =+C7-C8 -> 960 | D9: =+D7-D8 -> 1218 | E9: =+E7-E8 -> 1486.8 | G9: Utilidad bruta | H9: =C9/C$7 -> 0.4 | I9: =D9/D$7 -> 0.42 | J9: =E9/E$7 -> 0.43678026 | L9: Utilidad bruta | N9: =D9/C9-1 -> 0.26875 | O9: =E9/D9-1 -> 0.22068966 | Q9: Utilidad bruta | S9: =+D9-C9 -> 258 | T9: =+E9-D9 -> 268.8
B10: Gastos operativos | C10: =SUM(C11:C14) -> 720 | D10: =SUM(D11:D14) -> 858 | E10: =SUM(E11:E14) -> 944.2 | G10: Gastos operativos | H10: =C10/C$7 -> 0.3 | I10: =D10/D$7 -> 0.29586207 | J10: =E10/E$7 -> 0.27737955 | L10: Gastos operativos | N10: =D10/C10-1 -> 0.19166667 | O10: =E10/D10-1 -> 0.1004662 | Q10: Gastos operativos | S10: =+D10-C10 -> 138 | T10: =+E10-D10 -> 86.2
B11: Gastos de venta | C11: =+Notas!C20 -> 316 | D11: =+Notas!D20 -> 361 | E11: =+Notas!E20 -> 397.36 | G11: Gastos de venta | H11: =C11/C$7 -> 0.13166667 | I11: =D11/D$7 -> 0.12448276 | J11: =E11/E$7 -> 0.11673325 | L11: Gastos de venta | N11: =D11/C11-1 -> 0.14240506 | O11: =E11/D11-1 -> 0.10072022 | Q11: Gastos de venta | S11: =+D11-C11 -> 45 | T11: =+E11-D11 -> 36.36
B12: Gastos de administración | C12: =+Notas!C21 -> 301 | D12: =+Notas!D21 -> 381 | E12: =+Notas!E21 -> 427.84 | G12: Gastos de administración | H12: =C12/C$7 -> 0.12541667 | I12: =D12/D$7 -> 0.13137931 | J12: =E12/E$7 -> 0.12568743 | L12: Gastos de administración | N12: =D12/C12-1 -> 0.26578073 | O12: =E12/D12-1 -> 0.12293963 | Q12: Gastos de administración | S12: =+D12-C12 -> 80 | T12: =+E12-D12 -> 46.84
B13: Depreciación | C13: =+Notas!C22 -> 80 | D13: =+Notas!D22 -> 91 | E13: =+Notas!E22 -> 93 | G13: Depreciación | H13: =C13/C$7 -> 0.033333333 | I13: =D13/D$7 -> 0.03137931 | J13: =E13/E$7 -> 0.027320799 | L13: Depreciación | N13: =D13/C13-1 -> 0.1375 | O13: =E13/D13-1 -> 0.021978022 | Q13: Depreciación | S13: =+D13-C13 -> 11 | T13: =+E13-D13 -> 2
B14: Amortización | C14: =+Notas!C23 -> 23 | D14: =+Notas!D23 -> 25 | E14: =+Notas!E23 -> 26 | G14: Amortización | H14: =C14/C$7 -> 0.0095833333 | I14: =D14/D$7 -> 0.0086206897 | J14: =E14/E$7 -> 0.0076380729 | L14: Amortización | N14: =D14/C14-1 -> 0.086956522 | O14: =E14/D14-1 -> 0.04 | Q14: Amortización | S14: =+D14-C14 -> 2 | T14: =+E14-D14 -> 1
B15: Utilidad de operación | C15: =C9-C10 -> 240 | D15: =D9-D10 -> 360 | E15: =E9-E10 -> 542.6 | G15: Utilidad de operación | H15: =C15/C$7 -> 0.1 | I15: =D15/D$7 -> 0.12413793 | J15: =E15/E$7 -> 0.15940071 | L15: Utilidad de operación | N15: =D15/C15-1 -> 0.5 | O15: =E15/D15-1 -> 0.50722222 | Q15: Utilidad de operación | S15: =+D15-C15 -> 120 | T15: =+E15-D15 -> 182.6
B16: Gastos financieros | C16: =+Notas!C105 -> 50 | D16: =+Notas!D105 -> 60 | E16: =+Notas!E105 -> 55 | G16: Gastos financieros | H16: =C16/C$7 -> 0.020833333 | I16: =D16/D$7 -> 0.020689655 | J16: =E16/E$7 -> 0.016157462 | L16: Gastos financieros | N16: =D16/C16-1 -> 0.2 | O16: =E16/D16-1 -> -0.083333333 | Q16: Gastos financieros | S16: =+D16-C16 -> 10 | T16: =+E16-D16 -> -5
B17: Ingresos no operativos | C17: =+Notas!C28 -> 4 | D17: =+Notas!D28 -> 8 | E17: =+Notas!E28 -> 4 | G17: Ingresos no operativos | H17: =C17/C$7 -> 0.0016666667 | I17: =D17/D$7 -> 0.0027586207 | J17: =E17/E$7 -> 0.0011750881 | L17: Ingresos no operativos | N17: =D17/C17-1 -> 1 | O17: =E17/D17-1 -> -0.5 | Q17: Ingresos no operativos | S17: =+D17-C17 -> 4 | T17: =+E17-D17 -> -4
B18: Gastos no operativos | C18: =+Notas!C29 -> 4 | D18: =+Notas!D29 -> 4 | E18: =+Notas!E29 -> 6 | G18: Gastos no operativos | H18: =C18/C$7 -> 0.0016666667 | I18: =D18/D$7 -> 0.0013793103 | J18: =E18/E$7 -> 0.0017626322 | L18: Gastos no operativos | N18: =D18/C18-1 -> 0 | O18: =E18/D18-1 -> 0.5 | Q18: Gastos no operativos | S18: =+D18-C18 -> 0 | T18: =+E18-D18 -> 2
B19: Utilidad antes de impuestos y reserva legal | C19: =C15-C16+C17-C18 -> 190 | D19: =D15-D16+D17-D18 -> 304 | E19: =E15-E16+E17-E18 -> 485.6 | G19: Utilidad antes de impuestos y reserva legal | H19: =C19/C$7 -> 0.079166667 | I19: =D19/D$7 -> 0.10482759 | J19: =E19/E$7 -> 0.1426557 | L19: Utilidad antes de impuestos y reserva legal | N19: =D19/C19-1 -> 0.6 | O19: =E19/D19-1 -> 0.59736842 | Q19: Utilidad antes de impuestos y reserva legal | S19: =+D19-C19 -> 114 | T19: =+E19-D19 -> 181.6
B20: Impuestos | C20: =Notas!C33*EEFF!C19 -> 47.5 | D20: =Notas!D33*EEFF!D19 -> 76 | E20: =Notas!E33*EEFF!E19 -> 121.4 | G20: Impuestos | H20: =C20/C$7 -> 0.019791667 | I20: =D20/D$7 -> 0.026206897 | J20: =E20/E$7 -> 0.035663925 | L20: Impuestos | N20: =D20/C20-1 -> 0.6 | O20: =E20/D20-1 -> 0.59736842 | Q20: Impuestos | S20: =+D20-C20 -> 28.5 | T20: =+E20-D20 -> 45.4
B21: Reserva legal | C21: =Notas!C34*C19 -> 13.3 | D21: =Notas!D34*D19 -> 21.28 | E21: =Notas!E34*E19 -> 33.992 | G21: Reserva legal | H21: =C21/C$7 -> 0.0055416667 | I21: =D21/D$7 -> 0.007337931 | J21: =E21/E$7 -> 0.0099858989 | L21: Reserva legal | N21: =D21/C21-1 -> 0.6 | O21: =E21/D21-1 -> 0.59736842 | Q21: Reserva legal | S21: =+D21-C21 -> 7.98 | T21: =+E21-D21 -> 12.712
B22: Utilidad neta | C22: =C19-C20-C21 -> 129.2 | D22: =D19-D20-D21 -> 206.72 | E22: =E19-E20-E21 -> 330.208 | G22: Utilidad neta | H22: =C22/C$7 -> 0.053833333 | I22: =D22/D$7 -> 0.071282759 | J22: =E22/E$7 -> 0.097005875 | L22: Utilidad neta | N22: =D22/C22-1 -> 0.6 | O22: =E22/D22-1 -> 0.59736842 | Q22: Utilidad neta | S22: =+D22-C22 -> 77.52 | T22: =+E22-D22 -> 123.488
H23: =C23/C$7 -> 0 | I23: =D23/D$7 -> 0 | J23: =E23/E$7 -> 0
B24: EBITDA | C24: =C15+C14+C13 -> 343 | D24: =D15+D14+D13 -> 476 | E24: =E15+E14+E13 -> 661.6 | G24: EBITDA | H24: =C24/C$7 -> 0.14291667 | I24: =D24/D$7 -> 0.16413793 | J24: =E24/E$7 -> 0.19435958 | L24: EBITDA | N24: =D24/C24-1 -> 0.3877551 | O24: =E24/D24-1 -> 0.38991597 | Q24: EBITDA | S24: =+D24-C24 -> 133 | T24: =+E24-D24 -> 185.6
B25: Dividendos | C25: =+Notas!C129 -> 0 | D25: =+Notas!D129 -> 0 | E25: =+Notas!E129 -> 50 | G25: Dividendos | H25: =C25/C$7 -> 0 | I25: =D25/D$7 -> 0 | J25: =E25/E$7 -> 0.014688602 | L25: Dividendos | N25: 0 | O25: 1 | Q25: Dividendos | S25: =+D25-C25 -> 0 | T25: =+E25-D25 -> 50
B27: Balance general | C27: Año 1 | D27: Año 2 | E27: Año 3 | G27: BG (en % de activos totales) | H27: Año 1 | I27: Año 2 | J27: Año 3 | L27: BG (Cambio % | crecimiento) | M27: Año 1 | N27: Año 2 | O27: Año 3 | Q27: BG (Cambio $) | R27: Año 1 | S27: Año 2 | T27: Año 3
B28: Efectivo y equivalentes | C28: =+Notas!C43 -> 247.1 | D28: =+Notas!D43 -> 134.55 | E28: =+Notas!E43 -> 309.95 | G28: Efectivo y equivalentes | H28: =C28/(C$32+C$40) -> 0.13341612 | I28: =D28/(D$32+D$40) -> 0.064927858 | J28: =E28/(E$32+E$40) -> 0.12575567 | L28: Efectivo y equivalentes | N28: =D28/C28-1 -> -0.45548361 | O28: =E28/D28-1 -> 1.3036046 | Q28: Efectivo y equivalentes | S28: =D28-C28 -> -112.55 | T28: =E28-D28 -> 175.4
B29: Cuentas por cobrar | C29: =+Notas!C49 -> 430 | D29: =+Notas!D49 -> 590 | E29: =+Notas!E49 -> 748 | G29: Cuentas por cobrar | H29: =C29/(C$32+C$40) -> 0.23216889 | I29: =D29/(D$32+D$40) -> 0.28470781 | J29: =E29/(E$32+E$40) -> 0.30348521 | L29: Cuentas por cobrar | N29: =D29/C29-1 -> 0.37209302 | O29: =E29/D29-1 -> 0.26779661 | Q29: Cuentas por cobrar | S29: =D29-C29 -> 160 | T29: =E29-D29 -> 158
B30: Inventario | C30: =+Notas!C60 -> 170 | D30: =+Notas!D60 -> 300 | E30: =+Notas!E60 -> 350 | G30: Inventario | H30: =C30/(C$32+C$40) -> 0.0917877 | I30: =D30/(D$32+D$40) -> 0.14476668 | J30: =E30/(E$32+E$40) -> 0.14200511 | L30: Inventario | N30: =D30/C30-1 -> 0.76470588 | O30: =E30/D30-1 -> 0.16666667 | Q30: Inventario | S30: =D30-C30 -> 130 | T30: =E30-D30 -> 50
B31: Otros activos circulantes | C31: =+Notas!C64 -> 38 | D31: =+Notas!D64 -> 58 | E31: =+Notas!E64 -> 107 | G31: Otros activos circulantes | H31: =C31/(C$32+C$40) -> 0.020517251 | I31: =D31/(D$32+D$40) -> 0.027988226 | J31: =E31/(E$32+E$40) -> 0.043412991 | L31: Otros activos circulantes | N31: =D31/C31-1 -> 0.52631579 | O31: =E31/D31-1 -> 0.84482759 | Q31: Otros activos circulantes | S31: =D31-C31 -> 20 | T31: =E31-D31 -> 49
B32: Activos circulantes | C32: =+SUM(C28:C31) -> 885.1 | D32: =+SUM(D28:D31) -> 1082.55 | E32: =+SUM(E28:E31) -> 1514.95 | G32: Activos circulantes | H32: =C32/(C$32+C$40) -> 0.47788996 | I32: =D32/(D$32+D$40) -> 0.52239058 | J32: =E32/(E$32+E$40) -> 0.61465898 | L32: Activos circulantes | N32: =D32/C32-1 -> 0.22308214 | O32: =E32/D32-1 -> 0.39942728 | Q32: Activos circulantes | S32: =D32-C32 -> 197.45 | T32: =E32-D32 -> 432.4
B33: PPE bruto | C33: =+Notas!C72 -> 800 | D33: =+Notas!D72 -> 910 | E33: =+Notas!E72 -> 930 | G33: PPE bruto | H33: =C33/(C$32+C$40) -> 0.43194212 | I33: =D33/(D$32+D$40) -> 0.43912561 | J33: =E33/(E$32+E$40) -> 0.37732787 | L33: PPE bruto | N33: =D33/C33-1 -> 0.1375 | O33: =E33/D33-1 -> 0.021978022 | Q33: PPE bruto | S33: =D33-C33 -> 110 | T33: =E33-D33 -> 20
B34: (-) Depreciación acumulada | C34: =+Notas!C77 -> 80 | D34: =+Notas!D77 -> 171 | E34: =+Notas!E77 -> 264 | G34: (-) Depreciación acumulada | H34: =C34/(C$32+C$40) -> 0.043194212 | I34: =D34/(D$32+D$40) -> 0.08251701 | J34: =E34/(E$32+E$40) -> 0.10711243 | L34: (-) Depreciación acumulada | N34: =D34/C34-1 -> 1.1375 | O34: =E34/D34-1 -> 0.54385965 | Q34: (-) Depreciación acumulada | S34: =D34-C34 -> 91 | T34: =E34-D34 -> 93
B35: PPE neto | C35: =+Notas!C81 -> 720 | D35: =+Notas!D81 -> 739 | E35: =+Notas!E81 -> 666 | G35: PPE neto | H35: =C35/(C$32+C$40) -> 0.38874791 | I35: =D35/(D$32+D$40) -> 0.3566086 | J35: =E35/(E$32+E$40) -> 0.27021544 | L35: PPE neto | N35: =D35/C35-1 -> 0.026388889 | O35: =E35/D35-1 -> -0.098782138 | Q35: PPE neto | S35: =D35-C35 -> 19 | T35: =E35-D35 -> -73
B36: Intangible bruto | C36: =+Notas!C88 -> 230 | D36: =+Notas!D88 -> 250 | E36: =+Notas!E88 -> 260 | G36: Intangible bruto | H36: =C36/(C$32+C$40) -> 0.12418336 | I36: =D36/(D$32+D$40) -> 0.1206389 | J36: =E36/(E$32+E$40) -> 0.10548951 | L36: Intangible bruto | N36: =D36/C36-1 -> 0.086956522 | O36: =E36/D36-1 -> 0.04 | Q36: Intangible bruto | S36: =D36-C36 -> 20 | T36: =E36-D36 -> 10
B37: (-) Amortización acumulada | C37: =+Notas!C93 -> 23 | D37: =+Notas!D93 -> 48 | E37: =+Notas!E93 -> 74 | G37: (-) Amortización acumulada | H37: =C37/(C$32+C$40) -> 0.012418336 | I37: =D37/(D$32+D$40) -> 0.023162669 | J37: =E37/(E$32+E$40) -> 0.030023938 | L37: (-) Amortización acumulada | N37: =D37/C37-1 -> 1.0869565 | O37: =E37/D37-1 -> 0.54166667 | Q37: (-) Amortización acumulada | S37: =D37-C37 -> 25 | T37: =E37-D37 -> 26
B38: Intangible neto | C38: =+Notas!C97 -> 207 | D38: =+Notas!D97 -> 202 | E38: =+Notas!E97 -> 186 | G38: Intangible neto | H38: =C38/(C$32+C$40) -> 0.11176502 | I38: =D38/(D$32+D$40) -> 0.097476234 | J38: =E38/(E$32+E$40) -> 0.075465574 | L38: Intangible neto | N38: =D38/C38-1 -> -0.024154589 | O38: =E38/D38-1 -> -0.079207921 | Q38: Intangible neto | S38: =D38-C38 -> -5 | T38: =E38-D38 -> -16
B39: Otros activos no circulantes | C39: =+Notas!C65 -> 40 | D39: =+Notas!D65 -> 48.75 | E39: =+Notas!E65 -> 97.75 | G39: Otros activos no circulantes | H39: =C39/(C$32+C$40) -> 0.021597106 | I39: =D39/(D$32+D$40) -> 0.023524586 | J39: =E39/(E$32+E$40) -> 0.039659999 | L39: Otros activos no circulantes | N39: =D39/C39-1 -> 0.21875 | O39: =E39/D39-1 -> 1.0051282 | Q39: Otros activos no circulantes | S39: =D39-C39 -> 8.75 | T39: =E39-D39 -> 49
B40: Activos no circulantes | C40: =C35++C38+C39 -> 967 | D40: =D35++D38+D39 -> 989.75 | E40: =E35++E38+E39 -> 949.75 | G40: Activos no circulantes | H40: =C40/(C$32+C$40) -> 0.52211004 | I40: =D40/(D$32+D$40) -> 0.47760942 | J40: =E40/(E$32+E$40) -> 0.38534102 | L40: Activos no circulantes | N40: =D40/C40-1 -> 0.02352637 | O40: =E40/D40-1 -> -0.040414246 | Q40: Activos no circulantes | S40: =D40-C40 -> 22.75 | T40: =E40-D40 -> -40
B41: Préstamos de corto plazo | C41: =+Notas!C101 -> 136 | D41: =+Notas!D101 -> 88 | E41: =+Notas!E101 -> 126 | G41: Préstamos de corto plazo | H41: =C41/(C$32+C$40) -> 0.07343016 | I41: =D41/(D$32+D$40) -> 0.042464894 | J41: =E41/(E$32+E$40) -> 0.05112184 | L41: Préstamos de corto plazo | N41: =D41/C41-1 -> -0.35294118 | O41: =E41/D41-1 -> 0.43181818 | Q41: Préstamos de corto plazo | S41: =D41-C41 -> -48 | T41: =E41-D41 -> 38
B42: Porción circulante de la deuda de largo plazo | C42: =+Notas!C102 -> 60 | D42: =+Notas!D102 -> 70 | E42: =+Notas!E102 -> 72 | G42: Porción circulante de la deuda de largo plazo | H42: =C42/(C$32+C$40) -> 0.032395659 | I42: =D42/(D$32+D$40) -> 0.033778893 | J42: =E42/(E$32+E$40) -> 0.02921248 | L42: Porción circulante de la deuda de largo plazo | N42: =D42/C42-1 -> 0.16666667 | O42: =E42/D42-1 -> 0.028571429 | Q42: Porción circulante de la deuda de largo plazo | S42: =D42-C42 -> 10 | T42: =E42-D42 -> 2
B43: Proveedores | C43: =+Notas!C110 -> 300 | D43: =+Notas!D110 -> 360 | E43: =+Notas!E110 -> 370 | G43: Proveedores | H43: =C43/(C$32+C$40) -> 0.16197829 | I43: =D43/(D$32+D$40) -> 0.17372002 | J43: =E43/(E$32+E$40) -> 0.15011969 | L43: Proveedores | N43: =D43/C43-1 -> 0.2 | O43: =E43/D43-1 -> 0.027777778 | Q43: Proveedores | S43: =D43-C43 -> 60 | T43: =E43-D43 -> 10
...

Sheet Ratios
B2: Empresa "Andes Finance Group" S.A
B3: Indicadores | Ratios financieros
B5: Tipo | C5: Ratio | D5: Fórmula | E5: Condición clave | F5: Año 1 | G5: Año 2 | H5: Año 3 | I5: Interpretación
B6: Rentabilidad
C7: Margen operación | D7: Utilidad operación / Ventas | E7: Según industria (tendencia +) Ind. ≈ 18%, $900k anual | F7: =+EEFF!C15/EEFF!C7 -> 0.1 | G7: =+EEFF!D15/EEFF!D7 -> 0.12413793 | H7: =+EEFF!E15/EEFF!E7 -> 0.15940071 | I7: Seleccione un perfil
C8: Margen neto | D8: Utilidad neta / Ventas | E8: Según industria (tendencia +) Ind. ≈ 4.5%, $225k anual | F8: =+EEFF!C22/EEFF!C7 -> 0.053833333 | G8: =+EEFF!D22/EEFF!D7 -> 0.071282759 | H8: =+EEFF!E22/EEFF!E7 -> 0.097005875 | I8: Seleccione un perfil
C9: ROA | D9: Utilidad neta / Activo | E9: Según industria (tendencia +) Ind. ≈ 7% | F9: =+EEFF!C22/(EEFF!C32+EEFF!C40) -> 0.069758652 | G9: =+EEFF!D22/(EEFF!D32+EEFF!D40) -> 0.099753897 | H9: =+EEFF!E22/(EEFF!E32+EEFF!E40) -> 0.13397493 | I9: Seleccione un perfil
C10: ROE | D10: Utilidad neta / Patrimonio | E10: Según industria (tendencia +) Ind. ≈ 20% | F10: =+EEFF!C22/EEFF!C53 -> 0.17400673 | G10: =+EEFF!D22/EEFF!D53 -> 0.21300361 | H10: =+EEFF!E22/EEFF!E53 -> 0.25703121 | I10: Seleccione un perfil
B13: Liquidez
C14: Razón circulante | D14: Activo circulante / Pasivo circulante | E14: ≥ 1.0 | F14: =+EEFF!C32/EEFF!C45 -> 1.5366319 | G14: =+EEFF!D32/EEFF!D45 -> 1.9754562 | H14: =+EEFF!E32/EEFF!E45 -> 2.3671094 | I14: Seleccione un perfil
C15: Prueba ácida | D15: (Efectivo + Cuentas por cobrar) / Pasivo corriente | E15: ≥ 1.0 | F15: =+(EEFF!C28+EEFF!C29)/EEFF!C45 -> 1.1755208 | G15: =+(EEFF!D28+EEFF!D29)/EEFF!D45 -> 1.3221715 | H15: =+(EEFF!E28+EEFF!E29)/EEFF!E45 -> 1.6530469 | I15: Seleccione un perfil
B17: Solvencia
C18: Estructura de capital | D18: Pasivo / Patrimonio | E18: ≤ 2.5 | F18: =+(EEFF!C45+EEFF!C48)/EEFF!C53 -> 1.4944108 | G18: =+(EEFF!D45+EEFF!D48)/EEFF!D53 -> 1.1352911 | H18: =+(EEFF!E45+EEFF!E48)/EEFF!E53 -> 0.91850237 | I18: Seleccione un perfil
C19: Cobertura servicio de deuda | D19: EBITDA / (Gastos financieros + PCP + PCDLP) | E19: ≥ 1.25 | F19: =+EEFF!C24/(EEFF!C16+EEFF!C41+EEFF!C42) -> 1.3943089 | G19: =+EEFF!D24/(EEFF!D16+EEFF!D41+EEFF!D42) -> 2.1834862 | H19: =+EEFF!E24/(EEFF!E16+EEFF!E41+EEFF!E42) -> 2.6150198 | I19: Seleccione un perfil
B21: Operación
C22: Dias cuentas por cobrar | D22: (Cuentas por cobrar promedio*365)/Ventas | E22: Según industria (tendencia =) Ind. ≈ 80 | G22: =(((EEFF!D29+EEFF!C29)/2)*365)/EEFF!D7 -> 64.189655 | H22: =(((EEFF!E29+EEFF!D29)/2)*365)/EEFF!E7 -> 71.734724 | I22: Seleccione un perfil
C23: Rotación inventarios | D23: Costo de venta / Inventario promedio | E23: Según industria (tendencia =) Ind. ≈ 3.2 | G23: =EEFF!D8/(AVERAGE(EEFF!C30:D30)) -> 7.1574468 | H23: =EEFF!E8/(AVERAGE(EEFF!D30:E30)) -> 5.8990769 | I23: Seleccione un perfil
K25: Fuente de lista:
K26: Seleccione un perfil
K27: Perfil robusto
K28: Perfil estable
K29: Perfil débil

Sheet Hoja auxiliar tablas
B2: Año | C2: Tipo | D2: Monto | F2: Año | G2: Tipo de Ratio | H2: Valor | J2: Año | K2: Tipo de operación | L2: Valor | N2: Año | O2: Tipo | P2: Monto | R2: Año | S2: Tipo | T2: Monto
B3: 2023 | C3: Ingresos | D3: 2400 | F3: 2023 | G3: Margen operación | H3: ='Ratios'!F7 -> 0.1 | J3: 2024 | K3: Dias cuentas por cobrar | L3: ='Ratios'!G22 -> 64.189655 | N3: 2023 | O3: Activos circulantes | P3: 855 | R3: 2023 | S3: EBITDA | T3: 343
B4: 2023 | C4: Costos | D4: 1440 | F4: 2023 | G4: Margen neto | H4: ='Ratios'!F8 -> 0.053833333 | J4: 2024 | K4: Rotación inventarios | L4: ='Ratios'!G23 -> 7.1574468 | N4: 2023 | O4: Activos no circulantes | P4: 967 | R4: 2024 | S4: EBITDA | T4: 476
B5: 2023 | C5: Utilidad Neta | D5: 129 | F5: 2023 | G5: ROA | H5: ='Ratios'!F9 -> 0.069758652 | J5: 2025 | K5: Dias cuentas por cobrar | L5: ='Ratios'!H22 -> 71.734724 | N5: 2023 | O5: Pasivos circulantes | P5: 576 | R5: 2025 | S5: EBITDA | T5: 662
B6: 2024 | C6: Ingresos | D6: 2900 | F6: 2023 | G6: ROE | H6: ='Ratios'!F10 -> 0.17400673 | J6: 2025 | K6: Rotación inventarios | L6: ='Ratios'!H23 -> 5.8990769 | N6: 2023 | O6: Pasivos no circulantes | P6: 534
B7: 2024 | C7: Costos | D7: 1682 | F7: 2023 | G7: Razón circulante | H7: ='Ratios'!F14 -> 1.5366319 | N7: 2023 | O7: Capital contable | P7: 743
B8: 2024 | C8: Utilidad Neta | D8: 207 | F8: 2023 | G8: Prueba ácida | H8: ='Ratios'!F15 -> 1.1755208 | N8: 2024 | O8: Activos circulantes | P8: 1083
B9: 2025 | C9: Ingresos | D9: 3404 | F9: 2023 | G9: Estructura de capital | H9: ='Ratios'!F18 -> 1.4944108 | N9: 2024 | O9: Activos no circulantes | P9: 990
B10: 2025 | C10: Costos | D10: 1917 | F10: 2023 | G10: Cobertura servicio de deuda | H10: ='Ratios'!F19 -> 1.3943089 | N10: 2024 | O10: Pasivos circulantes | P10: 548
B11: 2025 | C11: Utilidad Neta | D11: 330 | F11: 2024 | G11: Margen operación | H11: ='Ratios'!G7 -> 0.12413793 | N11: 2024 | O11: Pasivos no circulantes | P11: 554
F12: 2024 | G12: Margen neto | H12: ='Ratios'!G8 -> 0.071282759 | N12: 2024 | O12: Capital contable | P12: 971
F13: 2024 | G13: ROA | H13: ='Ratios'!G9 -> 0.099753897 | N13: 2025 | O13: Activos circulantes | P13: 1515
F14: 2024 | G14: ROE | H14: ='Ratios'!G10 -> 0.21300361 | N14: 2025 | O14: Activos no circulantes | P14: 950
F15: 2024 | G15: Razón circulante | H15: ='Ratios'!G14 -> 1.9754562 | N15: 2025 | O15: Pasivos circulantes | P15: 640
F16: 2024 | G16: Prueba ácida | H16: ='Ratios'!G15 -> 1.3221715 | N16: 2025 | O16: Pasivos no circulantes | P16: 540
F17: 2024 | G17: Estructura de capital | H17: ='Ratios'!G18 -> 1.1352911 | N17: 2025 | O17: Capital contable | P17: 1285
F18: 2024 | G18: Cobertura servicio de deuda | H18: ='Ratios'!G19 -> 2.1834862
F19: 2025 | G19: Margen operación | H19: ='Ratios'!H7 -> 0.15940071
F20: 2025 | G20: Margen neto | H20: ='Ratios'!H8 -> 0.097005875
F21: 2025 | G21: ROA | H21: ='Ratios'!H9 -> 0.13397493
F22: 2025 | G22: ROE | H22: ='Ratios'!H10 -> 0.25703121
F23: 2025 | G23: Razón circulante | H23: ='Ratios'!H14 -> 2.3671094
F24: 2025 | G24: Prueba ácida | H24: ='Ratios'!H15 -> 1.6530469
F25: 2025 | G25: Estructura de capital | H25: ='Ratios'!H18 -> 0.91850237
F26: 2025 | G26: Cobertura servicio de deuda | H26: ='Ratios'!H19 -> 2.6150198

Sheet Hoja auxiliar TD
A2: Promedio de Monto | B2: Etiquetas de columna | G2: Suma de Valor | H2: Etiquetas de columna | M2: Suma de Monto | N2: Etiquetas de columna | R2: Suma de Monto | S2: Etiquetas de columna | W2: Suma de Monto | X2: Etiquetas de columna
A3: Etiquetas de fila | B3: Costos | C3: Ingresos | D3: Utilidad Neta | G3: Etiquetas de fila | H3: Margen neto | I3: Margen operación | M3: Etiquetas de fila | N3: 2023 | O3: 2024 | P3: 2025 | R3: Etiquetas de fila | S3: Capital contable | W3: Etiquetas de fila | X3: EBITDA | Y3: Total general
A4: 2023 | B4: 1440 | C4: 2400 | D4: 129 | G4: 2023 | H4: 0.053833333 | I4: 0.1 | M4: Activos circulantes | N4: 855 | O4: 1083 | P4: 1515 | R4: 2023 | S4: 743 | W4: 2023 | X4: 343 | Y4: 343
A5: 2024 | B5: 1682 | C5: 2900 | D5: 207 | G5: 2024 | H5: 0.071282759 | I5: 0.12413793 | M5: Activos no circulantes | N5: 967 | O5: 990 | P5: 950 | R5: 2024 | S5: 971 | W5: 2024 | X5: 476 | Y5: 476
A6: 2025 | B6: 1917 | C6: 3404 | D6: 330 | G6: 2025 | H6: 0.097005875 | I6: 0.15940071 | M6: Capital contable | N6: 743 | O6: 971 | P6: 1285 | R6: 2025 | S6: 1285 | W6: 2025 | X6: 662 | Y6: 662
M7: Pasivos circulantes | N7: 576 | O7: 548 | P7: 640 | W7: Total general | X7: 1481 | Y7: 1481
A8: Suma de Monto | B8: Etiquetas de columna | G8: Suma de Valor | H8: Etiquetas de columna | M8: Pasivos no circulantes | N8: 534 | O8: 554 | P8: 540
A9: Etiquetas de fila | B9: Utilidad Neta | G9: Etiquetas de fila | H9: Prueba ácida | I9: Razón circulante
A10: 2023 | B10: 129 | G10: 2023 | H10: 1.1755208 | I10: 1.5366319
A11: 2024 | B11: 207 | G11: 2024 | H11: 1.3221715 | I11: 1.9754562
A12: 2025 | B12: 330 | G12: 2025 | H12: 1.6530469 | I12: 2.3671094
G14: Suma de Valor | H14: Etiquetas de columna
G15: Etiquetas de fila | H15: Cobertura servicio de deuda | I15: Estructura de capital
G16: 2023 | H16: 1.3943089 | I16: 1.4944108
G17: 2024 | H17: 2.1834862 | I17: 1.1352911
G18: 2025 | H18: 2.6150198 | I18: 0.91850237
G21: Suma de Valor | H21: Etiquetas de columna
G22: Etiquetas de fila | H22: Dias cuentas por cobrar | I22: Rotación inventarios
G23: 2024 | H23: 64.189655 | I23: 7.1574468
G24: 2025 | H24: 71.734724 | I24: 5.8990769
G27: Suma de Valor | H27: Etiquetas de columna
G28: Etiquetas de fila | H28: ROA | I28: ROE
G29: 2023 | H29: 0.069758652 | I29: 0.17400673
G30: 2024 | H30: 0.099753897 | I30: 0.21300361
G31: 2025 | H31: 0.13397493 | I31: 0.25703121

Sheet dashboard estados

Sheet dashboard ratios
